<?xml version="1.0" encoding="utf-8"?>
<mujoco model="floating_base">
  <default>
    <geom friction="1 0.005 0.001" condim="3" margin="0.0005" solref="0.005 1"
      solimp="0.9999 0.9999 0.001 0.5 2" contype=" 1" conaffinity=" 1"></geom>
    <joint limited="true" damping="0.1" armature="0.001" margin="0.01" frictionloss="0.001"></joint>
    <site size="0.005" rgba="0.4 0.9 0.4 1"></site>
    <general ctrllimited="true" forcelimited="true"></general>
  </default>
  <option timestep="0.001" iterations="20" apirate="200">
    <flag warmstart="enable"></flag>
  </option>
  <compiler angle="radian" meshdir="../meshes/" />
  <worldbody>
    <body name="floating_base">
      <body name="translation_base">
        <inertial pos="0 0 0" quat="1 0 0 0" mass="0.01" diaginertia="0.01 0.01 0.01" />
        <joint name="ARTx" pos="0 0 0" axis="1 0 0" type="slide" range="-0.1 0.1" damping="20" />
        <body name="displace_1">
          <inertial pos="0 0 0" quat="1 0 0 0" mass="0.01" diaginertia="0.01 0.01 0.01" />
          <joint name="ARTy" pos="0 0 0" axis="0 1 0" type="slide" range="-0.1 0.1" damping="20" />
          <body name="displace_2">
            <inertial pos="0 0 0" quat="1 0 0 0" mass="0.01" diaginertia="0.01 0.01 0.01" />
            <joint name="ARTz" pos="0 0 0" axis="0 0 1" type="slide" range="-0.5 0.5" damping="20" />
            <body name="rotation_base">
              <inertial pos="0 0 0" quat="1 0 0 0" mass="0.01" diaginertia="0.01 0.01 0.01" />
              <joint name="ARRx" pos="0 0 0" axis="1 0 0" type="hinge" range="-2 2" damping="20" />
              <joint name="ARRy" pos="0 0 0" axis="0 1 0" type="hinge" range="0 0.2" damping="20" />
              <joint name="ARRz" pos="0 0 0" axis="0 0 1" type="hinge" range="-0.2 0.2"
                damping="20" />
              <body name="hand_base">
                <body name="right_hand_base" pos="0 0 0"
                  quat="0.7071067811865476 0.0 0.7071067811865475 0.0">
                  <geom pos="0 0 -0.17" quat="0.707388 0 0 -0.706825" type="mesh" contype="0"
                    conaffinity="0" group="1" density="0" rgba="0.3 0.3 0.3 1" mesh="r_p_link0" />
                  <geom pos="0 0 -0.17" quat="0.707388 0 0 -0.706825" type="mesh"
                    rgba="0.3 0.3 0.3 1"
                    mesh="r_p_link0" />
                  <geom pos="0.032685 0.023881 0.10707" quat="0.775137 0.151553 0.0221905 0.612945"
                    type="mesh" contype="0" conaffinity="0" group="1" density="0"
                    rgba="0.3 0.3 0.3 1"
                    mesh="r_p_link1" />
                  <geom pos="0.032685 0.023881 0.10707" quat="0.775137 0.151553 0.0221905 0.612945"
                    type="mesh" rgba="0.3 0.3 0.3 1" mesh="r_p_link1" />
                  <geom pos="0.032685 0.023881 0.10707" quat="0.775137 0.151553 0.0221905 0.612945"
                    type="mesh" contype="0" conaffinity="0" group="1" density="0"
                    rgba="0.3 0.3 0.3 1"
                    mesh="r_p_link3" />
                  <geom pos="0.032685 0.023881 0.10707" quat="0.775137 0.151553 0.0221905 0.612945"
                    type="mesh" rgba="0.3 0.3 0.3 1" mesh="r_p_link3" />
                  <geom pos="0.032685 0.023881 0.10707" quat="0.775137 0.151553 0.0221905 0.612945"
                    type="mesh" contype="0" conaffinity="0" group="1" density="0"
                    rgba="0.9 0.9 0.9 1"
                    mesh="r_p_link4" />
                  <geom pos="0.032685 0.023881 0.10707" quat="0.775137 0.151553 0.0221905 0.612945"
                    type="mesh" rgba="0.9 0.9 0.9 1" mesh="r_p_link4" />
                  <geom pos="0.032685 0.023881 0.10707" quat="0.775137 0.151553 0.0221905 0.612945"
                    type="mesh" contype="0" conaffinity="0" group="1" density="0"
                    rgba="0.3 0.3 0.3 1"
                    mesh="r_p_link5" />
                  <geom pos="0.032685 0.023881 0.10707" quat="0.775137 0.151553 0.0221905 0.612945"
                    type="mesh" rgba="0.3 0.3 0.3 1" mesh="r_p_link5" />
                  <geom pos="0.032685 0.023881 0.10707" quat="0.775137 0.151553 0.0221905 0.612945"
                    type="mesh" contype="0" conaffinity="0" group="1" density="0"
                    rgba="0.9 0.9 0.9 1"
                    mesh="r_p_link6" />
                  <geom pos="0.032685 0.023881 0.10707" quat="0.775137 0.151553 0.0221905 0.612945"
                    type="mesh" rgba="0.9 0.9 0.9 1" mesh="r_p_link6" />
                  <geom pos="0.032685 0.023881 0.10707" quat="0.775137 0.151553 0.0221905 0.612945"
                    type="mesh" contype="0" conaffinity="0" group="1" density="0"
                    rgba="0.9 0.9 0.9 1"
                    mesh="r_p_link2" />
                  <geom pos="0.032685 0.023881 0.10707" quat="0.775137 0.151553 0.0221905 0.612945"
                    type="mesh" rgba="0.9 0.9 0.9 1" mesh="r_p_link2" />
                  <body name="r_f_link1_1" pos="0.032685 0.023881 0.10707"
                    quat="0.775137 0.151553 0.0221905 0.612945">
                    <inertial pos="0.00205223 -0.000372643 -0.0185288"
                      quat="0.71769 0.0508968 0.0297657 0.693863" mass="0.00518035"
                      diaginertia="1.21881e-06 1.15459e-06 2.51191e-07" />
                    <joint name="r_f_joint1_1" pos="0 0 0" axis="0 0 -1" range="0 2.2"
                      actuatorfrcrange="-10 10" />
                    <geom type="mesh" contype="0" conaffinity="0" group="1" density="0"
                      rgba="0.3 0.3 0.3 1"
                      mesh="r_f_link1_1" />
                    <geom type="mesh" rgba="0.3 0.3 0.3 1" mesh="r_f_link1_1" />
                    <body name="r_f_link1_2" pos="0.0083307 0 0"
                      quat="0.707073 0.707076 0.0067524 -0.00675243">
                      <inertial pos="0.0217194 0.000635197 0.00102982"
                        quat="-0.0118779 0.705581 -0.0460466 0.707032" mass="0.00931794"
                        diaginertia="1.81442e-06 1.76774e-06 6.45119e-07" />
                      <joint name="r_f_joint1_2" pos="0 0 0" axis="0 0 1" range="0 1.3"
                        actuatorfrcrange="-10 10" />
                      <geom type="mesh" contype="0" conaffinity="0" group="1" density="0"
                        rgba="0.3 0.3 0.3 1" mesh="r_f_link1_2" />
                      <geom type="mesh" rgba="0.3 0.3 0.3 1" mesh="r_f_link1_2" />
                      <geom type="mesh" contype="0" conaffinity="0" group="1" density="0"
                        rgba="0.3 0.3 0.3 1" mesh="r_f_link1_2_1" />
                      <geom type="mesh" rgba="0.3 0.3 0.3 1" mesh="r_f_link1_2_1" />
                      <geom type="mesh" contype="0" conaffinity="0" group="1" density="0"
                        rgba="0.9 0.9 0.9 1" mesh="r_f_link1_2_2" />
                      <geom type="mesh" rgba="0.9 0.9 0.9 1" mesh="r_f_link1_2_2" />
                      <body name="r_f_link1_3" pos="0.043 0 0">
                        <inertial pos="0.0130893 -0.000676815 0.00129681"
                          quat="0.0232598 0.704008 -0.0263538 0.709322" mass="0.00492936"
                          diaginertia="4.30587e-07 4.03231e-07 2.21805e-07" />
                        <joint name="r_f_joint1_3" pos="0 0 0" axis="0 0 1" range="0 1.3"
                          actuatorfrcrange="-10 10" />
                        <geom type="mesh" contype="0" conaffinity="0" group="1" density="0"
                          rgba="0.3 0.3 0.3 1" mesh="r_f_link1_3" />
                        <geom type="mesh" rgba="0.3 0.3 0.3 1" mesh="r_f_link1_3" />
                        <geom type="mesh" contype="0" conaffinity="0" group="1" density="0"
                          rgba="0.3 0.3 0.3 1" mesh="r_f_link1_3_1" />
                        <geom type="mesh" rgba="0.3 0.3 0.3 1" mesh="r_f_link1_3_1" />
                        <geom type="mesh" contype="0" conaffinity="0" group="1" density="0"
                          rgba="0.9 0.9 0.9 1" mesh="r_f_link1_3_2" />
                        <geom type="mesh" rgba="0.9 0.9 0.9 1" mesh="r_f_link1_3_2" />
                        <body name="r_f_link1_4" pos="0.025 0 0">
                          <inertial pos="0.016544 -0.00270681 0.00177433"
                            quat="0.610025 0.485729 0.504629 0.370521" mass="0.00767734"
                            diaginertia="9.63011e-07 9.11997e-07 3.70573e-07" />
                          <joint name="r_f_joint1_4" pos="0 0 0" axis="0 0 1" range="0 1.3"
                            actuatorfrcrange="-10 10" />
                          <geom type="mesh" contype="0" conaffinity="0" group="1" density="0"
                            rgba="0.3 0.3 0.3 1" mesh="r_f_link1_4" />
                          <geom type="mesh" rgba="0.3 0.3 0.3 1" mesh="r_f_link1_4" />
                          <geom type="mesh" contype="0" conaffinity="0" group="1" density="0"
                            rgba="0.3 0.3 0.3 1" mesh="r_f_link1_4_1" />
                          <geom type="mesh" rgba="0.3 0.3 0.3 1" mesh="r_f_link1_4_1" />
                          <geom type="mesh" contype="0" conaffinity="0" group="1" density="0"
                            rgba="0.9 0.9 0.9 1" mesh="r_f_link1_4_2" />
                          <geom type="mesh" rgba="0.9 0.9 0.9 1" mesh="r_f_link1_4_2" />
                          <geom size="0.002" pos="0.035 -0.004 0" contype="0" conaffinity="0"
                            group="1"
                            density="0" rgba="1 0 0 1" />
                          <geom size="0.002" pos="0.02 0 0" rgba="1 0 0 1" />
                          <body name="r_f_link1_4_tensor" pos="0.025 0.0018 0" euler="0 0 -0.45">
                            <inertial pos="0 0 0" mass="0.0001" />
                            <geom type="box" name="geom_r_f_link1_4" size="0.006 0.001 0.003"
                              rgba="0  0 1 1" />
                            <site type="box" name="site_r_f_link1_4" size="0.006 0.001 0.003"
                              rgba="0  0 1 1" />
                          </body>
                        </body>
                      </body>
                    </body>
                  </body>
                  <body name="r_f_link2_1" pos="0.0069382 0.0349175 0.1597"
                    quat="0.000289373 -0.707107 -0.00029197 -0.707107">
                    <inertial pos="0.00800686 1.83389e-05 -0.00158423"
                      quat="0.366432 0.601227 0.609221 0.364834" mass="0.00351858"
                      diaginertia="3.71993e-07 3.23705e-07 2.04962e-07" />
                    <joint name="r_f_joint2_1" pos="0 0 0" axis="0 0 -1" range="0 0.6"
                      actuatorfrcrange="-10 10" />
                    <geom type="mesh" contype="0" conaffinity="0" group="1" density="0"
                      rgba="0.3 0.3 0.3 1"
                      mesh="r_f_link2_1" />
                    <geom type="mesh" rgba="0.3 0.3 0.3 1" mesh="r_f_link2_1" />
                    <body name="r_f_link2_2" pos="0.017 0 0" quat="0.707105 0.707108 0 0">
                      <inertial pos="0.0214625 -0.000312324 -0.000276541"
                        quat="0.514364 0.49694 0.502968 0.485286" mass="0.00860339"
                        diaginertia="1.79436e-06 1.76074e-06 5.64762e-07" />
                      <joint name="r_f_joint2_2" pos="0 0 0" axis="0 0 1" range="0 1.3"
                        actuatorfrcrange="-10 10" />
                      <geom type="mesh" contype="0" conaffinity="0" group="1" density="0"
                        rgba="0.3 0.3 0.3 1" mesh="r_f_link2_2" />
                      <geom type="mesh" rgba="0.3 0.3 0.3 1" mesh="r_f_link2_2" />
                      <geom type="mesh" contype="0" conaffinity="0" group="1" density="0"
                        rgba="0.3 0.3 0.3 1" mesh="r_f_link2_2_1" />
                      <geom type="mesh" rgba="0.3 0.3 0.3 1" mesh="r_f_link2_2_1" />
                      <geom type="mesh" contype="0" conaffinity="0" group="1" density="0"
                        rgba="0.9 0.9 0.9 1" mesh="r_f_link2_2_2" />
                      <geom type="mesh" rgba="0.9 0.9 0.9 1" mesh="r_f_link2_2_2" />
                      <body name="r_f_link2_3" pos="0.043 0 0">
                        <inertial pos="0.0131211 -0.000590719 -1.26084e-05"
                          quat="0.0239512 0.703828 -0.0289604 0.709375" mass="0.00474675"
                          diaginertia="4.25746e-07 3.96949e-07 2.15446e-07" />
                        <joint name="r_f_joint2_3" pos="0 0 0" axis="0 0 1" range="0 1.3"
                          actuatorfrcrange="-10 10" />
                        <geom type="mesh" contype="0" conaffinity="0" group="1" density="0"
                          rgba="0.3 0.3 0.3 1" mesh="r_f_link2_3" />
                        <geom type="mesh" rgba="0.3 0.3 0.3 1" mesh="r_f_link2_3" />
                        <geom type="mesh" contype="0" conaffinity="0" group="1" density="0"
                          rgba="0.3 0.3 0.3 1" mesh="r_f_link2_3_1" />
                        <geom type="mesh" rgba="0.3 0.3 0.3 1" mesh="r_f_link2_3_1" />
                        <geom type="mesh" contype="0" conaffinity="0" group="1" density="0"
                          rgba="0.9 0.9 0.9 1" mesh="r_f_link2_3_2" />
                        <geom type="mesh" rgba="0.9 0.9 0.9 1" mesh="r_f_link2_3_2" />
                        <body name="r_f_link2_4" pos="0.025 0 0">
                          <inertial pos="0.0165327 -0.00269728 0.000649365"
                            quat="0.616193 0.478635 0.507867 0.365085" mass="0.0076892"
                            diaginertia="9.75666e-07 9.11773e-07 3.80946e-07" />
                          <joint name="r_f_joint2_4" pos="0 0 0" axis="0 0 1" range="0 1.3"
                            actuatorfrcrange="-10 10" />
                          <geom type="mesh" contype="0" conaffinity="0" group="1" density="0"
                            rgba="0.3 0.3 0.3 1" mesh="r_f_link2_4" />
                          <geom type="mesh" rgba="0.3 0.3 0.3 1" mesh="r_f_link2_4" />
                          <geom type="mesh" contype="0" conaffinity="0" group="1" density="0"
                            rgba="0.3 0.3 0.3 1" mesh="r_f_link2_4_1" />
                          <geom type="mesh" rgba="0.3 0.3 0.3 1" mesh="r_f_link2_4_1" />
                          <geom type="mesh" contype="0" conaffinity="0" group="1" density="0"
                            rgba="0.9 0.9 0.9 1" mesh="r_f_link2_4_2" />
                          <geom type="mesh" rgba="0.9 0.9 0.9 1" mesh="r_f_link2_4_2" />
                          <geom size="0.002" pos="0.035 -0.004 0" contype="0" conaffinity="0"
                            group="1"
                            density="0" rgba="1 0 0 1" />
                          <geom size="0.002" pos="0.02 0 0" rgba="1 0 0 1" />
                          <body name="r_f_link2_4_tensor" pos="0.025 0.0018 0" euler="0 0 -0.45">
                            <inertial pos="0 0 0" mass="0.0001" />
                            <geom type="box" name="geom_r_f_link2_4" size="0.006 0.001 0.003"
                              rgba="0  0 1 1" />
                            <site type="box" name="site_r_f_link2_4" size="0.006 0.001 0.003"
                              rgba="0  0 1 1" />
                          </body>
                        </body>
                      </body>
                    </body>
                  </body>
                  <body name="r_f_link3_1" pos="0.00695755 0.0106175 0.1687"
                    quat="0.000278947 -0.707107 -0.000281544 -0.707107">
                    <inertial pos="0.00800686 1.83389e-05 -0.00158423"
                      quat="0.366432 0.601227 0.609221 0.364834" mass="0.00351858"
                      diaginertia="3.71993e-07 3.23705e-07 2.04962e-07" />
                    <joint name="r_f_joint3_1" pos="0 0 0" axis="0 0 1" range="-0.001 0.001"
                      actuatorfrcrange="-10 10" />
                    <geom type="mesh" contype="0" conaffinity="0" group="1" density="0"
                      rgba="0.9 0.9 0.9 1"
                      mesh="r_f_link3_1" />
                    <geom type="mesh" rgba="0.9 0.9 0.9 1" mesh="r_f_link3_1" />
                    <body name="r_f_link3_2" pos="0.017 0 0" quat="0.707105 0.707108 0 0">
                      <inertial pos="0.0214625 -0.000312324 -0.000276541"
                        quat="0.514364 0.49694 0.502968 0.485286" mass="0.00860339"
                        diaginertia="1.79436e-06 1.76074e-06 5.64762e-07" />
                      <joint name="r_f_joint3_2" pos="0 0 0" axis="0 0 1" range="0 1.3"
                        actuatorfrcrange="-10 10" />
                      <geom type="mesh" contype="0" conaffinity="0" group="1" density="0"
                        rgba="0.3 0.3 0.3 1" mesh="r_f_link3_2" />
                      <geom type="mesh" rgba="0.3 0.3 0.3 1" mesh="r_f_link3_2" />
                      <geom type="mesh" contype="0" conaffinity="0" group="1" density="0"
                        rgba="0.3 0.3 0.3 1" mesh="r_f_link3_2_1" />
                      <geom type="mesh" rgba="0.3 0.3 0.3 1" mesh="r_f_link3_2_1" />
                      <geom type="mesh" contype="0" conaffinity="0" group="1" density="0"
                        rgba="0.9 0.9 0.9 1" mesh="r_f_link3_2_2" />
                      <geom type="mesh" rgba="0.9 0.9 0.9 1" mesh="r_f_link3_2_2" />
                      <body name="r_f_link3_3" pos="0.043 0 0">
                        <inertial pos="0.0131211 -0.000590719 -1.26084e-05"
                          quat="0.0239512 0.703828 -0.0289604 0.709375" mass="0.00474675"
                          diaginertia="4.25746e-07 3.96949e-07 2.15446e-07" />
                        <joint name="r_f_joint3_3" pos="0 0 0" axis="0 0 1" range="0 1.3"
                          actuatorfrcrange="-10 10" />
                        <geom type="mesh" contype="0" conaffinity="0" group="1" density="0"
                          rgba="0.3 0.3 0.3 1" mesh="r_f_link3_3" />
                        <geom type="mesh" rgba="0.3 0.3 0.3 1" mesh="r_f_link3_3" />
                        <geom type="mesh" contype="0" conaffinity="0" group="1" density="0"
                          rgba="0.9 0.9 0.9 1" mesh="r_f_link3_3_1" />
                        <geom type="mesh" rgba="0.9 0.9 0.9 1" mesh="r_f_link3_3_1" />
                        <geom type="mesh" contype="0" conaffinity="0" group="1" density="0"
                          rgba="0.9 0.9 0.9 1" mesh="r_f_link3_3_2" />
                        <geom type="mesh" rgba="0.9 0.9 0.9 1" mesh="r_f_link3_3_2" />
                        <body name="r_f_link3_4" pos="0.025 0 0">
                          <inertial pos="0.0165327 -0.00269728 0.000649365"
                            quat="0.616193 0.478635 0.507867 0.365085" mass="0.0076892"
                            diaginertia="9.75666e-07 9.11773e-07 3.80946e-07" />
                          <joint name="r_f_joint3_4" pos="0 0 0" axis="0 0 1" range="0 1.3"
                            actuatorfrcrange="-10 10" />
                          <geom type="mesh" contype="0" conaffinity="0" group="1" density="0"
                            rgba="0.3 0.3 0.3 1" mesh="r_f_link3_4" />
                          <geom type="mesh" rgba="0.3 0.3 0.3 1" mesh="r_f_link3_4" />
                          <geom type="mesh" contype="0" conaffinity="0" group="1" density="0"
                            rgba="0.3 0.3 0.3 1" mesh="r_f_link3_4_1" />
                          <geom type="mesh" rgba="0.3 0.3 0.3 1" mesh="r_f_link3_4_1" />
                          <geom type="mesh" contype="0" conaffinity="0" group="1" density="0"
                            rgba="0.9 0.9 0.9 1" mesh="r_f_link3_4_2" />
                          <geom type="mesh" rgba="0.9 0.9 0.9 1" mesh="r_f_link3_4_2" />
                          <geom size="0.002" pos="0.035 -0.004 0" contype="0" conaffinity="0"
                            group="1"
                            density="0" rgba="1 0 0 1" />
                          <geom size="0.002" pos="0.02 0 0" rgba="1 0 0 1" />
                          <body name="r_f_link3_4_tensor" pos="0.025 0.0018 0" euler="0 0 -0.45">
                            <inertial pos="0 0 0" mass="0.0001" />
                            <geom type="box" name="geom_r_f_link3_4" size="0.006 0.001 0.003"
                              rgba="0  0 1 1" />
                            <site type="box" name="site_r_f_link3_4" size="0.006 0.001 0.003"
                              rgba="0  0 1 1" />
                          </body>
                        </body>
                      </body>
                    </body>
                  </body>
                  <body name="r_f_link4_1" pos="0.0069769 -0.0136824 0.1597"
                    quat="0.000278947 -0.707107 -0.000281544 -0.707107">
                    <inertial pos="0.00800686 1.83389e-05 -0.00158423"
                      quat="0.366432 0.601227 0.609221 0.364834" mass="0.00351858"
                      diaginertia="3.71993e-07 3.23705e-07 2.04962e-07" />
                    <joint name="r_f_joint4_1" pos="0 0 0" axis="0 0 1" range="0 0.6"
                      actuatorfrcrange="-10 10" />
                    <geom type="mesh" contype="0" conaffinity="0" group="1" density="0"
                      rgba="0.9 0.9 0.9 1"
                      mesh="r_f_link4_1" />
                    <geom type="mesh" rgba="0.9 0.9 0.9 1" mesh="r_f_link4_1" />
                    <body name="r_f_link4_2" pos="0.017 0 0" quat="0.707105 0.707108 0 0">
                      <inertial pos="0.0214625 -0.000312324 -0.000276541"
                        quat="0.514364 0.49694 0.502968 0.485286" mass="0.00860339"
                        diaginertia="1.79436e-06 1.76074e-06 5.64762e-07" />
                      <joint name="r_f_joint4_2" pos="0 0 0" axis="0 0 1" range="0 1.3"
                        actuatorfrcrange="-10 10" />
                      <geom type="mesh" contype="0" conaffinity="0" group="1" density="0"
                        rgba="0.3 0.3 0.3 1" mesh="r_f_link4_2" />
                      <geom type="mesh" rgba="0.3 0.3 0.3 1" mesh="r_f_link4_2" />
                      <geom type="mesh" contype="0" conaffinity="0" group="1" density="0"
                        rgba="0.3 0.3 0.3 1" mesh="r_f_link4_2_1" />
                      <geom type="mesh" rgba="0.3 0.3 0.3 1" mesh="r_f_link4_2_1" />
                      <geom type="mesh" contype="0" conaffinity="0" group="1" density="0"
                        rgba="0.9 0.9 0.9 1" mesh="r_f_link4_2_2" />
                      <geom type="mesh" rgba="0.9 0.9 0.9 1" mesh="r_f_link4_2_2" />
                      <body name="r_f_link4_3" pos="0.043 0 0">
                        <inertial pos="0.0131211 -0.000590719 -1.26084e-05"
                          quat="0.0239528 0.703828 -0.028962 0.709375" mass="0.00474675"
                          diaginertia="4.25746e-07 3.96949e-07 2.15446e-07" />
                        <joint name="r_f_joint4_3" pos="0 0 0" axis="0 0 1" range="0 1.3"
                          actuatorfrcrange="-10 10" />
                        <geom type="mesh" contype="0" conaffinity="0" group="1" density="0"
                          rgba="0.3 0.3 0.3 1" mesh="r_f_link4_3" />
                        <geom type="mesh" rgba="0.3 0.3 0.3 1" mesh="r_f_link4_3" />
                        <geom type="mesh" contype="0" conaffinity="0" group="1" density="0"
                          rgba="0.9 0.9 0.9 1" mesh="r_f_link4_3_2" />
                        <geom type="mesh" rgba="0.9 0.9 0.9 1" mesh="r_f_link4_3_2" />
                        <geom type="mesh" contype="0" conaffinity="0" group="1" density="0"
                          rgba="0.3 0.3 0.3 1" mesh="r_f_link4_3_1" />
                        <geom type="mesh" rgba="0.3 0.3 0.3 1" mesh="r_f_link4_3_1" />
                        <body name="r_f_link4_4" pos="0.025 0 0">
                          <inertial pos="0.0165327 -0.00269728 0.000649365"
                            quat="0.616193 0.478635 0.507867 0.365085" mass="0.0076892"
                            diaginertia="9.75666e-07 9.11773e-07 3.80946e-07" />
                          <joint name="r_f_joint4_4" pos="0 0 0" axis="0 0 1" range="0 1.3"
                            actuatorfrcrange="-10 10" />
                          <geom type="mesh" contype="0" conaffinity="0" group="1" density="0"
                            rgba="0.3 0.3 0.3 1" mesh="r_f_link4_4" />
                          <geom type="mesh" rgba="0.3 0.3 0.3 1" mesh="r_f_link4_4" />
                          <geom type="mesh" contype="0" conaffinity="0" group="1" density="0"
                            rgba="0.3 0.3 0.3 1" mesh="r_f_link4_4_1" />
                          <geom type="mesh" rgba="0.3 0.3 0.3 1" mesh="r_f_link4_4_1" />
                          <geom type="mesh" contype="0" conaffinity="0" group="1" density="0"
                            rgba="0.9 0.9 0.9 1" mesh="r_f_link4_4_2" />
                          <geom type="mesh" rgba="0.9 0.9 0.9 1" mesh="r_f_link4_4_2" />
                          <geom size="0.002" pos="0.035 -0.004 0" contype="0" conaffinity="0"
                            group="1"
                            density="0" rgba="1 0 0 1" />
                          <geom size="0.002" pos="0.02 0 0" rgba="1 0 0 1" />
                          <body name="r_f_link4_4_tensor" pos="0.025 0.0018 0" euler="0 0 -0.45">
                            <inertial pos="0 0 0" mass="0.0001" />
                            <geom type="box" name="geom_r_f_link4_4" size="0.006 0.001 0.003"
                              rgba="0  0 1 1" />
                            <site type="box" name="site_r_f_link4_4" size="0.006 0.001 0.003"
                              rgba="0  0 1 1" />
                          </body>
                        </body>
                      </body>
                    </body>
                  </body>
                  <body name="r_f_link5_1" pos="0.00699625 -0.0379824 0.1457"
                    quat="0.000278947 -0.707107 -0.000281544 -0.707107">
                    <inertial pos="0.00800686 1.83389e-05 -0.00158423"
                      quat="0.366432 0.601227 0.609221 0.364834" mass="0.00351858"
                      diaginertia="3.71993e-07 3.23705e-07 2.04962e-07" />
                    <joint name="r_f_joint5_1" pos="0 0 0" axis="0 0 1" range="0 0.6"
                      actuatorfrcrange="-10 10" />
                    <geom type="mesh" contype="0" conaffinity="0" group="1" density="0"
                      rgba="0.9 0.9 0.9 1"
                      mesh="r_f_link5_1" />
                    <geom type="mesh" rgba="0.9 0.9 0.9 1" mesh="r_f_link5_1" />
                    <body name="r_f_link5_2" pos="0.017 0 0" quat="0.707105 0.707108 0 0">
                      <inertial pos="0.0214625 -0.000312324 -0.000276541"
                        quat="0.514364 0.49694 0.502968 0.485286" mass="0.00860339"
                        diaginertia="1.79436e-06 1.76074e-06 5.64762e-07" />
                      <joint name="r_f_joint5_2" pos="0 0 0" axis="0 0 1" range="0 1.3"
                        actuatorfrcrange="-10 10" />
                      <geom type="mesh" contype="0" conaffinity="0" group="1" density="0"
                        rgba="0.3 0.3 0.3 1" mesh="r_f_link5_2" />
                      <geom type="mesh" rgba="0.3 0.3 0.3 1" mesh="r_f_link5_2" />
                      <geom type="mesh" contype="0" conaffinity="0" group="1" density="0"
                        rgba="0.3 0.3 0.3 1" mesh="r_f_link5_2_1" />
                      <geom type="mesh" rgba="0.3 0.3 0.3 1" mesh="r_f_link5_2_1" />
                      <geom type="mesh" contype="0" conaffinity="0" group="1" density="0"
                        rgba="0.9 0.9 0.9 1" mesh="r_f_link5_2_2" />
                      <geom type="mesh" rgba="0.9 0.9 0.9 1" mesh="r_f_link5_2_2" />
                      <body name="r_f_link5_3" pos="0.043 0 0">
                        <inertial pos="0.0131211 -0.000590719 -1.26084e-05"
                          quat="0.0239512 0.703828 -0.0289604 0.709375" mass="0.00474675"
                          diaginertia="4.25746e-07 3.96949e-07 2.15446e-07" />
                        <joint name="r_f_joint5_3" pos="0 0 0" axis="0 0 1" range="0 1.3"
                          actuatorfrcrange="-10 10" />
                        <geom type="mesh" contype="0" conaffinity="0" group="1" density="0"
                          rgba="0.3 0.3 0.3 1" mesh="r_f_link5_3" />
                        <geom type="mesh" rgba="0.3 0.3 0.3 1" mesh="r_f_link5_3" />
                        <geom type="mesh" contype="0" conaffinity="0" group="1" density="0"
                          rgba="0.3 0.3 0.3 1" mesh="r_f_link5_3_1" />
                        <geom type="mesh" rgba="0.3 0.3 0.3 1" mesh="r_f_link5_3_1" />
                        <geom type="mesh" contype="0" conaffinity="0" group="1" density="0"
                          rgba="0.9 0.9 0.9 1" mesh="r_f_link5_3_2" />
                        <geom type="mesh" rgba="0.9 0.9 0.9 1" mesh="r_f_link5_3_2" />
                        <body name="r_f_link5_4" pos="0.025 0 0">
                          <inertial pos="0.0165327 -0.00269728 0.000649365"
                            quat="0.616193 0.478635 0.507867 0.365085" mass="0.0076892"
                            diaginertia="9.75666e-07 9.11773e-07 3.80946e-07" />
                          <joint name="r_f_joint5_4" pos="0 0 0" axis="0 0 1" range="0 1.3"
                            actuatorfrcrange="-10 10" />
                          <geom type="mesh" contype="0" conaffinity="0" group="1" density="0"
                            rgba="0.3 0.3 0.3 1" mesh="r_f_link5_4" />
                          <geom type="mesh" rgba="0.3 0.3 0.3 1" mesh="r_f_link5_4" />
                          <geom type="mesh" contype="0" conaffinity="0" group="1" density="0"
                            rgba="0.3 0.3 0.3 1" mesh="r_f_link5_4_1" />
                          <geom type="mesh" rgba="0.3 0.3 0.3 1" mesh="r_f_link5_4_1" />
                          <geom type="mesh" contype="0" conaffinity="0" group="1" density="0"
                            rgba="0.9 0.9 0.9 1" mesh="r_f_link5_4_2" />
                          <geom type="mesh" rgba="0.9 0.9 0.9 1" mesh="r_f_link5_4_2" />
                          <geom size="0.002" pos="0.035 -0.004 0" contype="0" conaffinity="0"
                            group="1"
                            density="0" rgba="1 0 0 1" />
                          <geom size="0.002" pos="0.02 0 0" rgba="1 0 0 1" />
                          <body name="r_f_link5_4_tensor" pos="0.025 0.0018 0" euler="0 0 -0.45">
                            <inertial pos="0 0 0" mass="0.0001" />
                            <geom type="box" name="geom_r_f_link5_4" size="0.006 0.001 0.003"
                              rgba="0  0 1 1" />
                            <site type="box" name="site_r_f_link5_4" size="0.006 0.001 0.003"
                              rgba="0  0 1 1" />
                          </body>
                        </body>
                      </body>
                    </body>
                  </body>
                </body>
              </body>
            </body>
          </body>
        </body>
      </body>
    </body>
  </worldbody>
  <actuator>
    <position name="act_ARTx" joint="ARTx" kp="10000" kv="500" ctrlrange="-0.1 0.1"
      forcerange="-200 200" />
    <position name="act_ARTy" joint="ARTy" kp="10000" kv="500" ctrlrange="-0.1 0.1"
      forcerange="-200 200" />
    <position name="act_ARTz" joint="ARTz" kp="10000" kv="500" ctrlrange="-0.5 0.5"
      forcerange="-200 200" />
    <position name="act_ARRx" joint="ARRx" kp="10000" kv="500" ctrlrange="-2 2"
      forcerange="-20 20" />
    <position name="act_ARRy" joint="ARRy" kp="10000" kv="500" ctrlrange="0 0.2"
      forcerange="-20 20" />
    <position name="act_ARRz" joint="ARRz" kp="10000" kv="500" ctrlrange="-0.2 0.2"
      forcerange="-20 20" />
    <position name="act_r_f_joint1_2" joint="r_f_joint1_2" kp="20" kv="0.1" ctrlrange="0 1.3"
      forcerange="-20 20" />
    <position name="act_r_f_joint1_3" joint="r_f_joint1_3" kp="20" kv="0.1" ctrlrange="0 1.3"
      forcerange="-20 20" />
    <position name="act_r_f_joint1_4" joint="r_f_joint1_4" kp="20" kv="0.1" ctrlrange="0 1.3"
      forcerange="-20 20" />
    <position name="act_r_f_joint2_2" joint="r_f_joint2_2" kp="20" kv="0.1" ctrlrange="0 1.3"
      forcerange="-20 20" />
    <position name="act_r_f_joint2_3" joint="r_f_joint2_3" kp="20" kv="0.1" ctrlrange="0 1.3"
      forcerange="-20 20" />
    <position name="act_r_f_joint2_4" joint="r_f_joint2_4" kp="20" kv="0.1" ctrlrange="0 1.3"
      forcerange="-20 20" />
    <position name="act_r_f_joint3_2" joint="r_f_joint3_2" kp="20" kv="0.1" ctrlrange="0 1.3"
      forcerange="-20 20" />
    <position name="act_r_f_joint3_3" joint="r_f_joint3_3" kp="20" kv="0.1" ctrlrange="0 1.3"
      forcerange="-20 20" />
    <position name="act_r_f_joint3_4" joint="r_f_joint3_4" kp="20" kv="0.1" ctrlrange="0 1.3"
      forcerange="-20 20" />
    <position name="act_r_f_joint4_2" joint="r_f_joint4_2" kp="20" kv="0.1" ctrlrange="0 1.3"
      forcerange="-20 20" />
    <position name="act_r_f_joint4_3" joint="r_f_joint4_3" kp="20" kv="0.1" ctrlrange="0 1.3"
      forcerange="-20 20" />
    <position name="act_r_f_joint4_4" joint="r_f_joint4_4" kp="20" kv="0.1" ctrlrange="0 1.3"
      forcerange="-20 20" />
    <position name="act_r_f_joint5_2" joint="r_f_joint5_2" kp="20" kv="0.1" ctrlrange="0 1.3"
      forcerange="-20 20" />
    <position name="act_r_f_joint5_3" joint="r_f_joint5_3" kp="20" kv="0.1" ctrlrange="0 1.3"
      forcerange="-20 20" />
    <position name="act_r_f_joint5_4" joint="r_f_joint5_4" kp="20" kv="0.1" ctrlrange="0 1.3"
      forcerange="-20 20" />
    <position name="act_r_f_joint1_1" joint="r_f_joint1_1" kp="20" kv="1" ctrlrange="0 2.2"
      forcerange="-20 20" />
    <position name="act_r_f_joint2_1" joint="r_f_joint2_1" kp="20" kv="1" ctrlrange="0 0.3"
      forcerange="-20 20" />
    <position name="act_r_f_joint3_1" joint="r_f_joint3_1" kp="20" kv="1" ctrlrange="-0.0001 0.0001"
      forcerange="-20 20" />
    <position name="act_r_f_joint4_1" joint="r_f_joint4_1" kp="20" kv="1" ctrlrange="0 0.3"
      forcerange="-20 20" />
    <position name="act_r_f_joint5_1" joint="r_f_joint5_1" kp="20" kv="1" ctrlrange="0 0.6"
      forcerange="-20 20" />
  </actuator>
  <asset>
    <mesh name="r_p_link0" file="../meshes/r_p_link0.STL" />
    <mesh name="r_f_link1_1" file="../meshes/r_f_link1_1.STL" />
    <mesh name="r_f_link1_2" file="../meshes/r_f_link1_2.STL" />
    <mesh name="r_f_link1_3" file="../meshes/r_f_link1_3.STL" />
    <mesh name="r_f_link1_4" file="../meshes/r_f_link1_4.STL" />
    <mesh name="r_f_link1_4_1" file="../meshes/r_f_link1_4_1.STL" />
    <mesh name="r_f_link1_4_2" file="../meshes/r_f_link1_4_2.STL" />
    <mesh name="r_f_link1_3_1" file="../meshes/r_f_link1_3_1.STL" />
    <mesh name="r_f_link1_3_2" file="../meshes/r_f_link1_3_2.STL" />
    <mesh name="r_f_link1_2_1" file="../meshes/r_f_link1_2_1.STL" />
    <mesh name="r_f_link1_2_2" file="../meshes/r_f_link1_2_2.STL" />
    <mesh name="r_f_link2_1" file="../meshes/r_f_link2_1.STL" />
    <mesh name="r_f_link2_2" file="../meshes/r_f_link2_2.STL" />
    <mesh name="r_f_link2_3" file="../meshes/r_f_link2_3.STL" />
    <mesh name="r_f_link2_4" file="../meshes/r_f_link2_4.STL" />
    <mesh name="r_f_link2_4_1" file="../meshes/r_f_link2_4_1.STL" />
    <mesh name="r_f_link2_4_2" file="../meshes/r_f_link2_4_2.STL" />
    <mesh name="r_f_link2_3_1" file="../meshes/r_f_link2_3_1.STL" />
    <mesh name="r_f_link2_3_2" file="../meshes/r_f_link2_3_2.STL" />
    <mesh name="r_f_link2_2_1" file="../meshes/r_f_link2_2_1.STL" />
    <mesh name="r_f_link2_2_2" file="../meshes/r_f_link2_2_2.STL" />
    <mesh name="r_f_link3_1" file="../meshes/r_f_link3_1.STL" />
    <mesh name="r_f_link3_2" file="../meshes/r_f_link3_2.STL" />
    <mesh name="r_f_link3_3" file="../meshes/r_f_link3_3.STL" />
    <mesh name="r_f_link3_4" file="../meshes/r_f_link3_4.STL" />
    <mesh name="r_f_link3_4_1" file="../meshes/r_f_link3_4_1.STL" />
    <mesh name="r_f_link3_4_2" file="../meshes/r_f_link3_4_2.STL" />
    <mesh name="r_f_link3_3_1" file="../meshes/r_f_link3_3_1.STL" />
    <mesh name="r_f_link3_3_2" file="../meshes/r_f_link3_3_2.STL" />
    <mesh name="r_f_link3_2_1" file="../meshes/r_f_link3_2_1.STL" />
    <mesh name="r_f_link3_2_2" file="../meshes/r_f_link3_2_2.STL" />
    <mesh name="r_f_link4_1" file="../meshes/r_f_link4_1.STL" />
    <mesh name="r_f_link4_2" file="../meshes/r_f_link4_2.STL" />
    <mesh name="r_f_link4_3" file="../meshes/r_f_link4_3.STL" />
    <mesh name="r_f_link4_4" file="../meshes/r_f_link4_4.STL" />
    <mesh name="r_f_link4_4_1" file="../meshes/r_f_link4_4_1.STL" />
    <mesh name="r_f_link4_4_2" file="../meshes/r_f_link4_4_2.STL" />
    <mesh name="r_f_link4_3_2" file="../meshes/r_f_link4_3_2.STL" />
    <mesh name="r_f_link4_3_1" file="../meshes/r_f_link4_3_1.STL" />
    <mesh name="r_f_link4_2_1" file="../meshes/r_f_link4_2_1.STL" />
    <mesh name="r_f_link4_2_2" file="../meshes/r_f_link4_2_2.STL" />
    <mesh name="r_f_link5_1" file="../meshes/r_f_link5_1.STL" />
    <mesh name="r_f_link5_2" file="../meshes/r_f_link5_2.STL" />
    <mesh name="r_f_link5_3" file="../meshes/r_f_link5_3.STL" />
    <mesh name="r_f_link5_4" file="../meshes/r_f_link5_4.STL" />
    <mesh name="r_f_link5_4_1" file="../meshes/r_f_link5_4_1.STL" />
    <mesh name="r_f_link5_4_2" file="../meshes/r_f_link5_4_2.STL" />
    <mesh name="r_f_link5_3_1" file="../meshes/r_f_link5_3_1.STL" />
    <mesh name="r_f_link5_3_2" file="../meshes/r_f_link5_3_2.STL" />
    <mesh name="r_f_link5_2_1" file="../meshes/r_f_link5_2_1.STL" />
    <mesh name="r_f_link5_2_2" file="../meshes/r_f_link5_2_2.STL" />
    <mesh name="r_p_link1" file="../meshes/r_p_link1.STL" />
    <mesh name="r_p_link3" file="../meshes/r_p_link3.STL" />
    <mesh name="r_p_link4" file="../meshes/r_p_link4.STL" />
    <mesh name="r_p_link5" file="../meshes/r_p_link5.STL" />
    <mesh name="r_p_link6" file="../meshes/r_p_link6.STL" />
    <mesh name="r_p_link2" file="../meshes/r_p_link2.STL" />
  </asset>
  <sensor>
    <touch name="touch_r_f_link1_4" site="site_r_f_link1_4" />
    <touch name="touch_r_f_link2_4" site="site_r_f_link2_4" />
    <touch name="touch_r_f_link3_4" site="site_r_f_link3_4" />
    <touch name="touch_r_f_link4_4" site="site_r_f_link4_4" />
    <touch name="touch_r_f_link5_4" site="site_r_f_link5_4" />
  </sensor>
  <contact>
    <exclude body1="right_hand_base" body2="r_f_link1_1" />
    <exclude body1="right_hand_base" body2="r_f_link1_2" />
    <exclude body1="right_hand_base" body2="r_f_link1_3" />
    <exclude body1="right_hand_base" body2="r_f_link1_4" />
    <exclude body1="right_hand_base" body2="r_f_link2_1" />
    <exclude body1="right_hand_base" body2="r_f_link2_2" />
    <exclude body1="right_hand_base" body2="r_f_link2_3" />
    <exclude body1="right_hand_base" body2="r_f_link2_4" />
    <exclude body1="right_hand_base" body2="r_f_link3_1" />
    <exclude body1="right_hand_base" body2="r_f_link3_2" />
    <exclude body1="right_hand_base" body2="r_f_link3_3" />
    <exclude body1="right_hand_base" body2="r_f_link3_4" />
    <exclude body1="right_hand_base" body2="r_f_link4_1" />
    <exclude body1="right_hand_base" body2="r_f_link4_2" />
    <exclude body1="right_hand_base" body2="r_f_link4_3" />
    <exclude body1="right_hand_base" body2="r_f_link4_4" />
    <exclude body1="right_hand_base" body2="r_f_link5_1" />
    <exclude body1="right_hand_base" body2="r_f_link5_2" />
    <exclude body1="right_hand_base" body2="r_f_link5_3" />
    <exclude body1="right_hand_base" body2="r_f_link5_4" />
    <exclude body1="r_f_link1_1" body2="r_f_link1_2" />
    <exclude body1="r_f_link1_1" body2="r_f_link1_3" />
    <exclude body1="r_f_link1_1" body2="r_f_link1_4" />
    <exclude body1="r_f_link1_1" body2="r_f_link2_1" />
    <exclude body1="r_f_link1_1" body2="r_f_link2_2" />
    <exclude body1="r_f_link1_1" body2="r_f_link2_3" />
    <exclude body1="r_f_link1_1" body2="r_f_link2_4" />
    <exclude body1="r_f_link1_1" body2="r_f_link3_1" />
    <exclude body1="r_f_link1_1" body2="r_f_link3_2" />
    <exclude body1="r_f_link1_1" body2="r_f_link3_3" />
    <exclude body1="r_f_link1_1" body2="r_f_link3_4" />
    <exclude body1="r_f_link1_1" body2="r_f_link4_1" />
    <exclude body1="r_f_link1_1" body2="r_f_link4_2" />
    <exclude body1="r_f_link1_1" body2="r_f_link4_3" />
    <exclude body1="r_f_link1_1" body2="r_f_link4_4" />
    <exclude body1="r_f_link1_1" body2="r_f_link5_1" />
    <exclude body1="r_f_link1_1" body2="r_f_link5_2" />
    <exclude body1="r_f_link1_1" body2="r_f_link5_3" />
    <exclude body1="r_f_link1_1" body2="r_f_link5_4" />
    <exclude body1="r_f_link1_2" body2="r_f_link1_3" />
    <exclude body1="r_f_link1_2" body2="r_f_link1_4" />
    <exclude body1="r_f_link1_2" body2="r_f_link2_1" />
    <exclude body1="r_f_link1_2" body2="r_f_link2_2" />
    <exclude body1="r_f_link1_2" body2="r_f_link2_3" />
    <exclude body1="r_f_link1_2" body2="r_f_link2_4" />
    <exclude body1="r_f_link1_2" body2="r_f_link3_1" />
    <exclude body1="r_f_link1_2" body2="r_f_link3_2" />
    <exclude body1="r_f_link1_2" body2="r_f_link3_3" />
    <exclude body1="r_f_link1_2" body2="r_f_link3_4" />
    <exclude body1="r_f_link1_2" body2="r_f_link4_1" />
    <exclude body1="r_f_link1_2" body2="r_f_link4_2" />
    <exclude body1="r_f_link1_2" body2="r_f_link4_3" />
    <exclude body1="r_f_link1_2" body2="r_f_link4_4" />
    <exclude body1="r_f_link1_2" body2="r_f_link5_1" />
    <exclude body1="r_f_link1_2" body2="r_f_link5_2" />
    <exclude body1="r_f_link1_2" body2="r_f_link5_3" />
    <exclude body1="r_f_link1_2" body2="r_f_link5_4" />
    <exclude body1="r_f_link1_3" body2="r_f_link1_4" />
    <exclude body1="r_f_link1_3" body2="r_f_link2_1" />
    <exclude body1="r_f_link1_3" body2="r_f_link2_2" />
    <exclude body1="r_f_link1_3" body2="r_f_link2_3" />
    <exclude body1="r_f_link1_3" body2="r_f_link2_4" />
    <exclude body1="r_f_link1_3" body2="r_f_link3_1" />
    <exclude body1="r_f_link1_3" body2="r_f_link3_2" />
    <exclude body1="r_f_link1_3" body2="r_f_link3_3" />
    <exclude body1="r_f_link1_3" body2="r_f_link3_4" />
    <exclude body1="r_f_link1_3" body2="r_f_link4_1" />
    <exclude body1="r_f_link1_3" body2="r_f_link4_2" />
    <exclude body1="r_f_link1_3" body2="r_f_link4_3" />
    <exclude body1="r_f_link1_3" body2="r_f_link4_4" />
    <exclude body1="r_f_link1_3" body2="r_f_link5_1" />
    <exclude body1="r_f_link1_3" body2="r_f_link5_2" />
    <exclude body1="r_f_link1_3" body2="r_f_link5_3" />
    <exclude body1="r_f_link1_3" body2="r_f_link5_4" />
    <exclude body1="r_f_link1_4" body2="r_f_link2_1" />
    <exclude body1="r_f_link1_4" body2="r_f_link2_2" />
    <exclude body1="r_f_link1_4" body2="r_f_link2_3" />
    <exclude body1="r_f_link1_4" body2="r_f_link3_1" />
    <exclude body1="r_f_link1_4" body2="r_f_link3_2" />
    <exclude body1="r_f_link1_4" body2="r_f_link3_3" />
    <exclude body1="r_f_link1_4" body2="r_f_link4_1" />
    <exclude body1="r_f_link1_4" body2="r_f_link4_2" />
    <exclude body1="r_f_link1_4" body2="r_f_link4_3" />
    <exclude body1="r_f_link1_4" body2="r_f_link5_1" />
    <exclude body1="r_f_link1_4" body2="r_f_link5_2" />
    <exclude body1="r_f_link1_4" body2="r_f_link5_3" />
    <exclude body1="r_f_link2_1" body2="r_f_link2_2" />
    <exclude body1="r_f_link2_1" body2="r_f_link2_3" />
    <exclude body1="r_f_link2_1" body2="r_f_link2_4" />
    <exclude body1="r_f_link2_1" body2="r_f_link3_1" />
    <exclude body1="r_f_link2_1" body2="r_f_link3_2" />
    <exclude body1="r_f_link2_1" body2="r_f_link3_3" />
    <exclude body1="r_f_link2_1" body2="r_f_link3_4" />
    <exclude body1="r_f_link2_1" body2="r_f_link4_1" />
    <exclude body1="r_f_link2_1" body2="r_f_link4_2" />
    <exclude body1="r_f_link2_1" body2="r_f_link4_3" />
    <exclude body1="r_f_link2_1" body2="r_f_link4_4" />
    <exclude body1="r_f_link2_1" body2="r_f_link5_1" />
    <exclude body1="r_f_link2_1" body2="r_f_link5_2" />
    <exclude body1="r_f_link2_1" body2="r_f_link5_3" />
    <exclude body1="r_f_link2_1" body2="r_f_link5_4" />
    <exclude body1="r_f_link2_2" body2="r_f_link2_3" />
    <exclude body1="r_f_link2_2" body2="r_f_link2_4" />
    <exclude body1="r_f_link2_2" body2="r_f_link3_1" />
    <exclude body1="r_f_link2_2" body2="r_f_link3_2" />
    <exclude body1="r_f_link2_2" body2="r_f_link3_3" />
    <exclude body1="r_f_link2_2" body2="r_f_link3_4" />
    <exclude body1="r_f_link2_2" body2="r_f_link4_1" />
    <exclude body1="r_f_link2_2" body2="r_f_link4_2" />
    <exclude body1="r_f_link2_2" body2="r_f_link4_3" />
    <exclude body1="r_f_link2_2" body2="r_f_link4_4" />
    <exclude body1="r_f_link2_2" body2="r_f_link5_1" />
    <exclude body1="r_f_link2_2" body2="r_f_link5_2" />
    <exclude body1="r_f_link2_2" body2="r_f_link5_3" />
    <exclude body1="r_f_link2_2" body2="r_f_link5_4" />
    <exclude body1="r_f_link2_3" body2="r_f_link2_4" />
    <exclude body1="r_f_link2_3" body2="r_f_link3_1" />
    <exclude body1="r_f_link2_3" body2="r_f_link3_2" />
    <exclude body1="r_f_link2_3" body2="r_f_link3_3" />
    <exclude body1="r_f_link2_3" body2="r_f_link3_4" />
    <exclude body1="r_f_link2_3" body2="r_f_link4_1" />
    <exclude body1="r_f_link2_3" body2="r_f_link4_2" />
    <exclude body1="r_f_link2_3" body2="r_f_link4_3" />
    <exclude body1="r_f_link2_3" body2="r_f_link4_4" />
    <exclude body1="r_f_link2_3" body2="r_f_link5_1" />
    <exclude body1="r_f_link2_3" body2="r_f_link5_2" />
    <exclude body1="r_f_link2_3" body2="r_f_link5_3" />
    <exclude body1="r_f_link2_3" body2="r_f_link5_4" />
    <exclude body1="r_f_link2_4" body2="r_f_link3_1" />
    <exclude body1="r_f_link2_4" body2="r_f_link3_2" />
    <exclude body1="r_f_link2_4" body2="r_f_link3_3" />
    <exclude body1="r_f_link2_4" body2="r_f_link4_1" />
    <exclude body1="r_f_link2_4" body2="r_f_link4_2" />
    <exclude body1="r_f_link2_4" body2="r_f_link4_3" />
    <exclude body1="r_f_link2_4" body2="r_f_link5_1" />
    <exclude body1="r_f_link2_4" body2="r_f_link5_2" />
    <exclude body1="r_f_link2_4" body2="r_f_link5_3" />
    <exclude body1="r_f_link3_1" body2="r_f_link3_2" />
    <exclude body1="r_f_link3_1" body2="r_f_link3_3" />
    <exclude body1="r_f_link3_1" body2="r_f_link3_4" />
    <exclude body1="r_f_link3_1" body2="r_f_link4_1" />
    <exclude body1="r_f_link3_1" body2="r_f_link4_2" />
    <exclude body1="r_f_link3_1" body2="r_f_link4_3" />
    <exclude body1="r_f_link3_1" body2="r_f_link4_4" />
    <exclude body1="r_f_link3_1" body2="r_f_link5_1" />
    <exclude body1="r_f_link3_1" body2="r_f_link5_2" />
    <exclude body1="r_f_link3_1" body2="r_f_link5_3" />
    <exclude body1="r_f_link3_1" body2="r_f_link5_4" />
    <exclude body1="r_f_link3_2" body2="r_f_link3_3" />
    <exclude body1="r_f_link3_2" body2="r_f_link3_4" />
    <exclude body1="r_f_link3_2" body2="r_f_link4_1" />
    <exclude body1="r_f_link3_2" body2="r_f_link4_2" />
    <exclude body1="r_f_link3_2" body2="r_f_link4_3" />
    <exclude body1="r_f_link3_2" body2="r_f_link4_4" />
    <exclude body1="r_f_link3_2" body2="r_f_link5_1" />
    <exclude body1="r_f_link3_2" body2="r_f_link5_2" />
    <exclude body1="r_f_link3_2" body2="r_f_link5_3" />
    <exclude body1="r_f_link3_2" body2="r_f_link5_4" />
    <exclude body1="r_f_link3_3" body2="r_f_link3_4" />
    <exclude body1="r_f_link3_3" body2="r_f_link4_1" />
    <exclude body1="r_f_link3_3" body2="r_f_link4_2" />
    <exclude body1="r_f_link3_3" body2="r_f_link4_3" />
    <exclude body1="r_f_link3_3" body2="r_f_link4_4" />
    <exclude body1="r_f_link3_3" body2="r_f_link5_1" />
    <exclude body1="r_f_link3_3" body2="r_f_link5_2" />
    <exclude body1="r_f_link3_3" body2="r_f_link5_3" />
    <exclude body1="r_f_link3_3" body2="r_f_link5_4" />
    <exclude body1="r_f_link3_4" body2="r_f_link4_1" />
    <exclude body1="r_f_link3_4" body2="r_f_link4_2" />
    <exclude body1="r_f_link3_4" body2="r_f_link4_3" />
    <exclude body1="r_f_link3_4" body2="r_f_link5_1" />
    <exclude body1="r_f_link3_4" body2="r_f_link5_2" />
    <exclude body1="r_f_link3_4" body2="r_f_link5_3" />
    <exclude body1="r_f_link4_1" body2="r_f_link4_2" />
    <exclude body1="r_f_link4_1" body2="r_f_link4_3" />
    <exclude body1="r_f_link4_1" body2="r_f_link4_4" />
    <exclude body1="r_f_link4_1" body2="r_f_link5_1" />
    <exclude body1="r_f_link4_1" body2="r_f_link5_2" />
    <exclude body1="r_f_link4_1" body2="r_f_link5_3" />
    <exclude body1="r_f_link4_1" body2="r_f_link5_4" />
    <exclude body1="r_f_link4_2" body2="r_f_link4_3" />
    <exclude body1="r_f_link4_2" body2="r_f_link4_4" />
    <exclude body1="r_f_link4_2" body2="r_f_link5_1" />
    <exclude body1="r_f_link4_2" body2="r_f_link5_2" />
    <exclude body1="r_f_link4_2" body2="r_f_link5_3" />
    <exclude body1="r_f_link4_2" body2="r_f_link5_4" />
    <exclude body1="r_f_link4_3" body2="r_f_link4_4" />
    <exclude body1="r_f_link4_3" body2="r_f_link5_1" />
    <exclude body1="r_f_link4_3" body2="r_f_link5_2" />
    <exclude body1="r_f_link4_3" body2="r_f_link5_3" />
    <exclude body1="r_f_link4_3" body2="r_f_link5_4" />
    <exclude body1="r_f_link4_4" body2="r_f_link5_1" />
    <exclude body1="r_f_link4_4" body2="r_f_link5_2" />
    <exclude body1="r_f_link4_4" body2="r_f_link5_3" />
    <exclude body1="r_f_link5_1" body2="r_f_link5_2" />
    <exclude body1="r_f_link5_1" body2="r_f_link5_3" />
    <exclude body1="r_f_link5_1" body2="r_f_link5_4" />
    <exclude body1="r_f_link5_2" body2="r_f_link5_3" />
    <exclude body1="r_f_link5_2" body2="r_f_link5_4" />
    <exclude body1="r_f_link5_3" body2="r_f_link5_4" />
  </contact>
</mujoco>